Workbook

Sheet 1. Data Quality
A1: Data quality review — 4sight sample dataset
A2: 1,038 rows, 19-Nov-2015 to 06-Jan-2020. I ran seven checks; all seven found problems.
A4: # | B4: Check | C4: Problems found | D4: What was wrong | E4: What I did
A5: 1 | B5: Dates must be trading days | C5: 5 rows | D5: Rows dated on 2 weekends and on 04-Jul-2017 (market holiday). Their prices copy a nearby day. | E5: Deleted the 5 rows
A6: 2 | B6: High must be the day's highest price, Low the lowest | C6: 8 rows | D6: e.g. 07-Mar-2018 has Low 157.22 but Open 154.46. Impossible. | E6: High = max(O,H,L,C), Low = min(O,H,L,C)
A7: 3 | B7: Prices must be positive | C7: 1 row | D7: 10-Oct-2018 Adj Close is -152.28. | E7: Flipped the sign
A8: 4 | B8: Close must sit inside the day's High-Low range | C8: 1 row | D8: 19-Mar-2018 Close is 196.28 but the day's range is 154.45-157.21. Looks like 156.28 typed as 196.28. | E8: Corrected to 156.28
A9: 5 | B9: Adj Close / Close should drift slowly, never jump | C9: 2 rows | D9: 05-Dec-2016 and 27-Mar-2017 Adj Close are higher than Close (+40 and +30 off). | E9: Rebuilt from the neighbouring day's ratio
A10: 6 | B10: No price should freeze while the others move | C10: 11 rows | D10: 08-22 Sep 2017: Close stuck at 139.110001 for 11 days while Open/High/Low keep moving. On 10 of those days it sits below the day's own Low. | E10: Set to blank; asked the vendor to re-send
A11: 7 | B11: No missing values, no missing days | C11: 6 + 5 rows | D11: The last 6 Signals are exactly 0 — but the Signal never goes below 10.58 anywhere else, so 0 means "missing". Separately, the week of 12-16 Nov 2018 is absent entirely. | E11: Set the zeros to blank; flagged the missing week
B13: 34 rows affected in total. None of these are judgement calls — every one breaks a rule that must hold in any price file.

Sheet 2. Signal Analysis
A1: Is the 4sight signal any good?
A2: Short answer: no. It is mostly just the ETF price, and the rest of it was built using future prices.
A4: Finding 1 — the signal is mostly just the price
B5: Correlation between Signal and the same-day price | C5: =CORREL('3. Cleaned Data'!$B$4:$B$1041,'3. Cleaned Data'!$H$4:$H$1041) -> 0.93751735
B6: Signal is roughly the price divided by | C6: =1/SLOPE('3. Cleaned Data'!$B$4:$B$1041,'3. Cleaned Data'!$H$4:$H$1041) -> 7.3103462
B7: So most of the "signal" is information we already have on any price screen.
A9: Finding 2 — the rest of it comes from the future (this is the key result)
A10: I stripped the price out of the signal and asked: does what is left match the market BEFORE or AFTER its own date?
A11: A forecast made today can only use today's information. It cannot match tomorrow better than yesterday.
B13: day | C13: correlation | D13: knowable on the day?
B14: -5 | C14: =CORREL(OFFSET('3. Cleaned Data'!$J$9,0,0,1033,1),OFFSET('3. Cleaned Data'!$I$4,0,0,1033,1)) -> -0.023454611 | D14: yes — the past
B15: -4 | C15: =CORREL(OFFSET('3. Cleaned Data'!$J$8,0,0,1034,1),OFFSET('3. Cleaned Data'!$I$4,0,0,1034,1)) -> -0.056303727 | D15: yes — the past
B16: -3 | C16: =CORREL(OFFSET('3. Cleaned Data'!$J$7,0,0,1035,1),OFFSET('3. Cleaned Data'!$I$4,0,0,1035,1)) -> -0.0059522677 | D16: yes — the past
B17: -2 | C17: =CORREL(OFFSET('3. Cleaned Data'!$J$6,0,0,1036,1),OFFSET('3. Cleaned Data'!$I$4,0,0,1036,1)) -> -0.018589523 | D17: yes — the past
B18: -1 | C18: =CORREL(OFFSET('3. Cleaned Data'!$J$5,0,0,1037,1),OFFSET('3. Cleaned Data'!$I$4,0,0,1037,1)) -> -0.015554268 | D18: yes — the past
B19: 0 | C19: =CORREL(OFFSET('3. Cleaned Data'!$J$4,0,0,1038,1),OFFSET('3. Cleaned Data'!$I$4,0,0,1038,1)) -> -0.019871592 | D19: yes — today
B20: 1 | C20: =CORREL(OFFSET('3. Cleaned Data'!$J$4,0,0,1037,1),OFFSET('3. Cleaned Data'!$I$5,0,0,1037,1)) -> 0.15621082 | D20: NO — the future
B21: 2 | C21: =CORREL(OFFSET('3. Cleaned Data'!$J$4,0,0,1036,1),OFFSET('3. Cleaned Data'!$I$6,0,0,1036,1)) -> 0.17913678 | D21: NO — the future
B22: 3 | C22: =CORREL(OFFSET('3. Cleaned Data'!$J$4,0,0,1035,1),OFFSET('3. Cleaned Data'!$I$7,0,0,1035,1)) -> 0.19939017 | D22: NO — the future
B23: 4 | C23: =CORREL(OFFSET('3. Cleaned Data'!$J$4,0,0,1034,1),OFFSET('3. Cleaned Data'!$I$8,0,0,1034,1)) -> 0.12376621 | D23: NO — the future
B24: 5 | C24: =CORREL(OFFSET('3. Cleaned Data'!$J$4,0,0,1033,1),OFFSET('3. Cleaned Data'!$I$9,0,0,1033,1)) -> 0.14489654 | D24: NO — the future
B25: 6 | C25: =CORREL(OFFSET('3. Cleaned Data'!$J$4,0,0,1032,1),OFFSET('3. Cleaned Data'!$I$10,0,0,1032,1)) -> 0.12856923 | D25: NO — the future
B26: 7 | C26: =CORREL(OFFSET('3. Cleaned Data'!$J$4,0,0,1031,1),OFFSET('3. Cleaned Data'!$I$11,0,0,1031,1)) -> 0.0016967556 | D26: NO — the future
B28: Zero against everything up to today. Strong for the next six days. Then zero again.
B29: A genuine forecast cannot look like this. The signal was built from prices 3-7 days ahead of its own date.
A31: Finding 3 — that is why the backtest looks so good
C32: annual return | D32: Sharpe ratio
B33: Trading the signal | C33: 0.1715 | D33: 1.52
B34: Just holding the ETF | C34: 0.1054 | D34: 0.7
B35: (Sharpe = return per unit of risk. Around 0.7 is normal for the market; 1.5 from one simple rule is not believable.)
B36: Computed on the cleaned data — see the Python script. These two numbers are pasted, everything else on this sheet is a live formula.

Sheet 3. Cleaned Data
A1: Cleaned data — amber cells were changed or removed
A3: Date | B3: Signal | C3: Open | D3: High | E3: Low | F3: Close | G3: Adj Close | H3: Price used for analysis | I3: Daily return | J3: Signal minus price
A4: 42327 | B4: 13.76854 | C4: 116.44 | D4: 116.65 | E4: 115.74 | F4: 116.06 | G4: 108.2816 | H4: 108.2816 | J4: =IF(COUNT(B4)=0,"",B4-(INTERCEPT('3. Cleaned Data'!$B$4:$B$1041,'3. Cleaned Data'!$H$4:$H$1041)+SLOPE('3. Cleaned Data'!$B$4:$B$1041,'3. Cleaned Data'!$H$4:$H$1041)*H4)) -> 0.75418652
A5: 42328 | B5: 13.608819 | C5: 116.48 | D5: 117.36 | E5: 116.38 | F5: 116.81 | G5: 108.98132 | H5: 108.98132 | I5: =H5/H4-1 -> 0.0064620581 | J5: =IF(COUNT(B5)=0,"",B5-(INTERCEPT('3. Cleaned Data'!$B$4:$B$1041,'3. Cleaned Data'!$H$4:$H$1041)+SLOPE('3. Cleaned Data'!$B$4:$B$1041,'3. Cleaned Data'!$H$4:$H$1041)*H5)) -> 0.49874886
A6: 42331 | B6: 12.990589 | C6: 116.71 | D6: 117.89 | E6: 116.68 | F6: 117.39 | G6: 109.52245 | H6: 109.52245 | I6: =H6/H5-1 -> 0.0049653462 | J6: =IF(COUNT(B6)=0,"",B6-(INTERCEPT('3. Cleaned Data'!$B$4:$B$1041,'3. Cleaned Data'!$H$4:$H$1041)+SLOPE('3. Cleaned Data'!$B$4:$B$1041,'3. Cleaned Data'!$H$4:$H$1041)*H6)) -> -0.19350344
A7: 42332 | B7: 12.667435 | C7: 116.88 | D7: 118.42 | E7: 116.56 | F7: 118.25 | G7: 110.32484 | H7: 110.32484 | I7: =H7/H6-1 -> 0.0073262055 | J7: =IF(COUNT(B7)=0,"",B7-(INTERCEPT('3. Cleaned Data'!$B$4:$B$1041,'3. Cleaned Data'!$H$4:$H$1041)+SLOPE('3. Cleaned Data'!$B$4:$B$1041,'3. Cleaned Data'!$H$4:$H$1041)*H7)) -> -0.62641733
A8: 42333 | B8: 13.01991 | C8: 118.3 | D8: 119.32 | E8: 118.11 | F8: 119.17 | G8: 111.18316 | H8: 111.18316 | I8: =H8/H7-1 -> 0.0077799526 | J8: =IF(COUNT(B8)=0,"",B8-(INTERCEPT('3. Cleaned Data'!$B$4:$B$1041,'3. Cleaned Data'!$H$4:$H$1041)+SLOPE('3. Cleaned Data'!$B$4:$B$1041,'3. Cleaned Data'!$H$4:$H$1041)*H8)) -> -0.39135429
A9: 42335 | B9: 12.879819 | C9: 119.27 | D9: 119.9 | E9: 118.88 | F9: 119.62 | G9: 111.603 | H9: 111.603 | I9: =H9/H8-1 -> 0.0037760935 | J9: =IF(COUNT(B9)=0,"",B9-(INTERCEPT('3. Cleaned Data'!$B$4:$B$1041,'3. Cleaned Data'!$H$4:$H$1041)+SLOPE('3. Cleaned Data'!$B$4:$B$1041,'3. Cleaned Data'!$H$4:$H$1041)*H9)) -> -0.58887584
A10: 42338 | B10: 13.184791 | C10: 120.02 | D10: 120.07 | E10: 119.05 | F10: 119.1 | G10: 111.11785 | H10: 111.11785 | I10: =H10/H9-1 -> -0.0043470696 | J10: =IF(COUNT(B10)=0,"",B10-(INTERCEPT('3. Cleaned Data'!$B$4:$B$1041,'3. Cleaned Data'!$H$4:$H$1041)+SLOPE('3. Cleaned Data'!$B$4:$B$1041,'3. Cleaned Data'!$H$4:$H$1041)*H10)) -> -0.21753921
A11: 42339 | B11: 12.922631 | C11: 119.61 | D11: 119.91 | E11: 118.9 | F11: 119.89 | G11: 111.8549 | H11: 111.8549 | I11: =H11/H10-1 -> 0.0066330116 | J11: =IF(COUNT(B11)=0,"",B11-(INTERCEPT('3. Cleaned Data'!$B$4:$B$1041,'3. Cleaned Data'!$H$4:$H$1041)+SLOPE('3. Cleaned Data'!$B$4:$B$1041,'3. Cleaned Data'!$H$4:$H$1041)*H11)) -> -0.5805215
A12: 42340 | B12: 13.118076 | C12: 119.73 | D12: 120.04 | E12: 118.45 | F12: 118.6 | G12: 110.65137 | H12: 110.65137 | I12: =H12/H11-1 -> -0.010759743 | J12: =IF(COUNT(B12)=0,"",B12-(INTERCEPT('3. Cleaned Data'!$B$4:$B$1041,'3. Cleaned Data'!$H$4:$H$1041)+SLOPE('3. Cleaned Data'!$B$4:$B$1041,'3. Cleaned Data'!$H$4:$H$1041)*H12)) -> -0.2204436
A13: 42341 | B13: 12.91654 | C13: 118.93 | D13: 119.45 | E13: 116.14 | F13: 116.6 | G13: 108.78541 | H13: 108.78541 | I13: =H13/H12-1 -> -0.016863407 | J13: =IF(COUNT(B13)=0,"",B13-(INTERCEPT('3. Cleaned Data'!$B$4:$B$1041,'3. Cleaned Data'!$H$4:$H$1041)+SLOPE('3. Cleaned Data'!$B$4:$B$1041,'3. Cleaned Data'!$H$4:$H$1041)*H13)) -> -0.16673016
A14: 42342 | B14: 13.155278 | C14: 116.6 | D14: 117.93 | E14: 116.34 | F14: 117.78 | G14: 109.88632 | H14: 109.88632 | I14: =H14/H13-1 -> 0.010120052 | J14: =IF(COUNT(B14)=0,"",B14-(INTERCEPT('3. Cleaned Data'!$B$4:$B$1041,'3. Cleaned Data'!$H$4:$H$1041)+SLOPE('3. Cleaned Data'!$B$4:$B$1041,'3. Cleaned Data'!$H$4:$H$1041)*H14)) -> -0.078588819
A15: 42345 | B15: 12.430221 | C15: 117.64 | D15: 117.67 | E15: 115.51 | F15: 116.01 | G15: 108.23495 | H15: 108.23495 | I15: =H15/H14-1 -> -0.015028031 | J15: =IF(COUNT(B15)=0,"",B15-(INTERCEPT('3. Cleaned Data'!$B$4:$B$1041,'3. Cleaned Data'!$H$4:$H$1041)+SLOPE('3. Cleaned Data'!$B$4:$B$1041,'3. Cleaned Data'!$H$4:$H$1041)*H15)) -> -0.57775013
A16: 42346 | B16: 13.030335 | C16: 114.96 | D16: 116.01 | E16: 114.46 | F16: 115.37 | G16: 107.63783 | H16: 107.63783 | I16: =H16/H15-1 -> -0.0055168318 | J16: =IF(COUNT(B16)=0,"",B16-(INTERCEPT('3. Cleaned Data'!$B$4:$B$1041,'3. Cleaned Data'!$H$4:$H$1041)+SLOPE('3. Cleaned Data'!$B$4:$B$1041,'3. Cleaned Data'!$H$4:$H$1041)*H16)) -> 0.10404463
... A457: 42986 | B457: 15.518587 | C457: 138.92999 | D457: 139.77 | E457: 138.61999 | F457: 139.11 | G457: 133.3212 | H457: 133.3212 | I457: =H457/H456-1 -> 0 | J457: =IF(COUNT(B457)=0,"",B457-(INTERCEPT('3. Cleaned Data'!$B$4:$B$1041,'3. Cleaned Data'!$H$4:$H$1041)+SLOPE('3. Cleaned Data'!$B$4:$B$1041,'3. Cleaned Data'!$H$4:$H$1041)*H457)) -> -0.92099295
A458: 42989 | B458: 15.838558 | C458: 140.39 | D458: 140.92 | E458: 140.23 | H458: 133.79081 | I458: =H458/H457-1 -> 0.0035223745 | J458: =IF(COUNT(B458)=0,"",B458-(INTERCEPT('3. Cleaned Data'!$B$4:$B$1041,'3. Cleaned Data'!$H$4:$H$1041)+SLOPE('3. Cleaned Data'!$B$4:$B$1041,'3. Cleaned Data'!$H$4:$H$1041)*H458)) -> -0.66526078
A459: 42990 | B459: 15.518587 | C459: 141.03999 | D459: 141.69 | E459: 140.82001 | H459: 134.26041 | I459: =H459/H458-1 -> 0.0035100109 | J459: =IF(COUNT(B459)=0,"",B459-(INTERCEPT('3. Cleaned Data'!$B$4:$B$1041,'3. Cleaned Data'!$H$4:$H$1041)+SLOPE('3. Cleaned Data'!$B$4:$B$1041,'3. Cleaned Data'!$H$4:$H$1041)*H459)) -> -1.0494704
A460: 42991 | B460: 16.158529 | C460: 141.41 | D460: 142.22 | E460: 141.32001 | H460: 134.73002 | I460: =H460/H459-1 -> 0.0034977338 | J460: =IF(COUNT(B460)=0,"",B460-(INTERCEPT('3. Cleaned Data'!$B$4:$B$1041,'3. Cleaned Data'!$H$4:$H$1041)+SLOPE('3. Cleaned Data'!$B$4:$B$1041,'3. Cleaned Data'!$H$4:$H$1041)*H460)) -> -0.47376732
A461: 42992 | B461: 16.4785 | C461: 141.78 | D461: 142.16 | E461: 141.42 | H461: 135.19963 | I461: =H461/H460-1 -> 0.0034855423 | J461: =IF(COUNT(B461)=0,"",B461-(INTERCEPT('3. Cleaned Data'!$B$4:$B$1041,'3. Cleaned Data'!$H$4:$H$1041)+SLOPE('3. Cleaned Data'!$B$4:$B$1041,'3. Cleaned Data'!$H$4:$H$1041)*H461)) -> -0.21803515
A462: 42993 | B462: 15.198617 | C462: 141.64 | D462: 142.47 | E462: 141.55 | H462: 135.66923 | I462: =H462/H461-1 -> 0.0034734355 | J462: =IF(COUNT(B462)=0,"",B462-(INTERCEPT('3. Cleaned Data'!$B$4:$B$1041,'3. Cleaned Data'!$H$4:$H$1041)+SLOPE('3. Cleaned Data'!$B$4:$B$1041,'3. Cleaned Data'!$H$4:$H$1041)*H462)) -> -1.5621574
A463: 42996 | B463: 15.518587 | C463: 142.61999 | D463: 143.81 | E463: 142.60001 | H463: 136.13884 | I463: =H463/H462-1 -> 0.0034614125 | J463: =IF(COUNT(B463)=0,"",B463-(INTERCEPT('3. Cleaned Data'!$B$4:$B$1041,'3. Cleaned Data'!$H$4:$H$1041)+SLOPE('3. Cleaned Data'!$B$4:$B$1041,'3. Cleaned Data'!$H$4:$H$1041)*H463)) -> -1.3064252
A464: 42997 | B464: 16.798471 | C464: 143.57001 | D464: 143.69 | E464: 143.09 | H464: 136.60845 | I464: =H464/H463-1 -> 0.0034494725 | J464: =IF(COUNT(B464)=0,"",B464-(INTERCEPT('3. Cleaned Data'!$B$4:$B$1041,'3. Cleaned Data'!$H$4:$H$1041)+SLOPE('3. Cleaned Data'!$B$4:$B$1041,'3. Cleaned Data'!$H$4:$H$1041)*H464)) -> -0.090780394
A465: 42998 | B465: 15.953688 | C465: 143.53 | D465: 144.02 | E465: 143.26 | H465: 137.07806 | I465: =H465/H464-1 -> 0.0034376145 | J465: =IF(COUNT(B465)=0,"",B465-(INTERCEPT('3. Cleaned Data'!$B$4:$B$1041,'3. Cleaned Data'!$H$4:$H$1041)+SLOPE('3. Cleaned Data'!$B$4:$B$1041,'3. Cleaned Data'!$H$4:$H$1041)*H465)) -> -0.99980182
A466: 42999 | B466: 16.004491 | C466: 144.02 | D466: 144.26 | E466: 143.48 | H466: 137.54766 | I466: =H466/H465-1 -> 0.0034258378 | J466: =IF(COUNT(B466)=0,"",B466-(INTERCEPT('3. Cleaned Data'!$B$4:$B$1041,'3. Cleaned Data'!$H$4:$H$1041)+SLOPE('3. Cleaned Data'!$B$4:$B$1041,'3. Cleaned Data'!$H$4:$H$1041)*H466)) -> -1.0132379
A467: 43000 | B467: 16.9976 | C467: 143.67 | D467: 144.67 | E467: 143.56 | H467: 138.01727 | I467: =H467/H466-1 -> 0.0034141415 | J467: =IF(COUNT(B467)=0,"",B467-(INTERCEPT('3. Cleaned Data'!$B$4:$B$1041,'3. Cleaned Data'!$H$4:$H$1041)+SLOPE('3. Cleaned Data'!$B$4:$B$1041,'3. Cleaned Data'!$H$4:$H$1041)*H467)) -> -0.084367422
A468: 43003 | B468: 17.042562 | C468: 144.27 | D468: 144.94 | E468: 143.69 | F468: 144.5 | G468: 138.48688 | H468: 138.48688 | I468: =H468/H467-1 -> 0.0034025248 | J468: =IF(COUNT(B468)=0,"",B468-(INTERCEPT('3. Cleaned Data'!$B$4:$B$1041,'3. Cleaned Data'!$H$4:$H$1041)+SLOPE('3. Cleaned Data'!$B$4:$B$1041,'3. Cleaned Data'!$H$4:$H$1041)*H468)) -> -0.10364453
A469: 43004 | B469: 17.766227 | C469: 144.28999 | D469: 145.14999 | E469: 144.17999 | F469: 144.61 | G469: 138.92787 | H469: 138.92787 | I469: =H469/H468-1 -> 0.0031843811 | J469: =IF(COUNT(B469)=0,"",B469-(INTERCEPT('3. Cleaned Data'!$B$4:$B$1041,'3. Cleaned Data'!$H$4:$H$1041)+SLOPE('3. Cleaned Data'!$B$4:$B$1041,'3. Cleaned Data'!$H$4:$H$1041)*H469)) -> 0.55969629
A470: 43005 | B470: 17.638584 | C470: 145.63001 | D470: 147.86 | E470: 145.16 | F470: 147.44 | G470: 141.64667 | H470: 141.64667 | I470: =H470/H469-1 -> 0.019569831 | J470: =IF(COUNT(B470)=0,"",B470-(INTERCEPT('3. Cleaned Data'!$B$4:$B$1041,'3. Cleaned Data'!$H$4:$H$1041)+SLOPE('3. Cleaned Data'!$B$4:$B$1041,'3. Cleaned Data'!$H$4:$H$1041)*H470)) -> 0.060142556
A471: 43006 | B471: 17.157467 | C471: 147.25 | D471: 148.06 | E471: 146.78 | F471: 147.83 | G471: 142.02135 | H471: 142.02135 | I471: =H471/H470-1 -> 0.0026451734 | J471: =IF(COUNT(B471)=0,"",B471-(INTERCEPT('3. Cleaned Data'!$B$4:$B$1041,'3. Cleaned Data'!$H$4:$H$1041)+SLOPE('3. Cleaned Data'!$B$4:$B$1041,'3. Cleaned Data'!$H$4:$H$1041)*H471)) -> -0.47222753
A472: 43007 | B472: 18.139211 | C472: 147.92 | D472: 148.42999 | E472: 147.74 | F472: 148.17999 | G472: 142.35759 | H472: 142.35759 | I472: =H472/H471-1 -> 0.0023675525 | J472: =IF(COUNT(B472)=0,"",B472-(INTERCEPT('3. Cleaned Data'!$B$4:$B$1041,'3. Cleaned Data'!$H$4:$H$1041)+SLOPE('3. Cleaned Data'!$B$4:$B$1041,'3. Cleaned Data'!$H$4:$H$1041)*H472)) -> 0.46352034
A473: 43010 | B473: 18.01561 | C473: 148.31 | D473: 150 | E473: 148.08 | F473: 150 | G473: 144.10608 | H473: 144.10608 | I473: =H473/H472-1 -> 0.012282373 | J473: =IF(COUNT(B473)=0,"",B473-(INTERCEPT('3. Cleaned Data'!$B$4:$B$1041,'3. Cleaned Data'!$H$4:$H$1041)+SLOPE('3. Cleaned Data'!$B$4:$B$1041,'3. Cleaned Data'!$H$4:$H$1041)*H473)) -> 0.10073963
A474: 43011 | B474: 16.952524 | C474: 150.11 | D474: 150.33 | E474: 149.33 | F474: 150.33 | G474: 144.42313 | H474: 144.42313 | I474: =H474/H473-1 -> 0.0022000946 | J474: =IF(COUNT(B474)=0,"",B474-(INTERCEPT('3. Cleaned Data'!$B$4:$B$1041,'3. Cleaned Data'!$H$4:$H$1041)+SLOPE('3. Cleaned Data'!$B$4:$B$1041,'3. Cleaned Data'!$H$4:$H$1041)*H474)) -> -1.0057163
A475: 43012 | B475: 17.916097 | C475: 150.09 | D475: 150.61 | E475: 149.39 | F475: 149.85001 | G475: 143.96199 | H475: 143.96199 | I475: =H475/H474-1 -> -0.0031929512 | J475: =IF(COUNT(B475)=0,"",B475-(INTERCEPT('3. Cleaned Data'!$B$4:$B$1041,'3. Cleaned Data'!$H$4:$H$1041)+SLOPE('3. Cleaned Data'!$B$4:$B$1041,'3. Cleaned Data'!$H$4:$H$1041)*H475)) -> 0.020937138
A476: 43013 | B476: 16.585523 | C476: 150.28999 | D476: 150.63001 | E476: 149.86999 | F476: 150.26 | G476: 144.35585 | H476: 144.35585 | I476: =H476/H475-1 -> 0.002735861 | J476: =IF(COUNT(B476)=0,"",B476-(INTERCEPT('3. Cleaned Data'!$B$4:$B$1041,'3. Cleaned Data'!$H$4:$H$1041)+SLOPE('3. Cleaned Data'!$B$4:$B$1041,'3. Cleaned Data'!$H$4:$H$1041)*H476)) -> -1.3635138
A477: 43014 | B477: 17.954465 | C477: 149.71001 | D477: 150.34 | E477: 149.57001 | F477: 150.05 | G477: 144.15411 | H477: 144.15411 | I477: =H477/H476-1 -> -0.001397491 | J477: =IF(COUNT(B477)=0,"",B477-(INTERCEPT('3. Cleaned Data'!$B$4:$B$1041,'3. Cleaned Data'!$H$4:$H$1041)+SLOPE('3. Cleaned Data'!$B$4:$B$1041,'3. Cleaned Data'!$H$4:$H$1041)*H477)) -> 0.033023793
A478: 43017 | B478: 17.768762 | C478: 150.19 | D478: 150.67999 | E478: 149.17999 | F478: 149.42999 | G478: 143.55847 | H478: 143.55847 | I478: =H478/H477-1 -> -0.0041319806 | J478: =IF(COUNT(B478)=0,"",B478-(INTERCEPT('3. Cleaned Data'!$B$4:$B$1041,'3. Cleaned Data'!$H$4:$H$1041)+SLOPE('3. Cleaned Data'!$B$4:$B$1041,'3. Cleaned Data'!$H$4:$H$1041)*H478)) -> -0.071200252
A479: 43018 | B479: 17.564505 | C479: 149.92999 | D479: 150.28999 | E479: 149.41 | F479: 149.86 | G479: 143.97156 | H479: 143.97156 | I479: =H479/H478-1 -> 0.0028774756 | J479: =IF(COUNT(B479)=0,"",B479-(INTERCEPT('3. Cleaned Data'!$B$4:$B$1041,'3. Cleaned Data'!$H$4:$H$1041)+SLOPE('3. Cleaned Data'!$B$4:$B$1041,'3. Cleaned Data'!$H$4:$H$1041)*H479)) -> -0.33196447
... A753: 43413 | B753: 19.074848 | C753: 156 | D753: 156.03 | E753: 152.95 | F753: 154.08 | G753: 149.86568 | H753: 149.86568 | I753: =H753/H752-1 -> -0.018536257 | J753: =IF(COUNT(B753)=0,"",B753-(INTERCEPT('3. Cleaned Data'!$B$4:$B$1041,'3. Cleaned Data'!$H$4:$H$1041)+SLOPE('3. Cleaned Data'!$B$4:$B$1041,'3. Cleaned Data'!$H$4:$H$1041)*H753)) -> 0.37210812
A754: 43416 | H754: 149.01947 | I754: =H754/H753-1 -> -0.0056464174 | J754: =IF(COUNT(B754)=0,"",B754-(INTERCEPT('3. Cleaned Data'!$B$4:$B$1041,'3. Cleaned Data'!$H$4:$H$1041)+SLOPE('3. Cleaned Data'!$B$4:$B$1041,'3. Cleaned Data'!$H$4:$H$1041)*H754))
...
